在C++协程（coroutines）中，`unhandled_exception` 是 `std::coroutine_traits` 和 `promise_type` 的一个成员函数，用于处理协程中未捕获的异常。当协程函数内部抛出一个异常且没有被协程内部捕获时，这个异常会被传递到 `promise_type` 的 `unhandled_exception` 函数中。

默认情况下，`unhandled_exception` 的实现通常会调用 `std::terminate`，这会导致程序终止。但是，你可以自定义 `promise_type` 并提供你自己的 `unhandled_exception` 实现，以执行自定义的异常处理逻辑。

以下是一个简单的例子，展示了如何自定义 `promise_type` 并提供 `unhandled_exception` 的实现：

```cpp
#include <coroutine>
#include <iostream>
#include <exception>

// 自定义的 promise 类型
struct my_promise_type {
    std::suspend_always initial_suspend() { return {}; }
    std::suspend_always final_suspend() noexcept { return {}; }

    // 自定义的 unhandled_exception 实现
    void unhandled_exception() {
        try {
            throw; // 重新抛出未处理的异常
        } catch (const std::exception& e) {
            std::cerr << "Caught an exception in the coroutine: " << e.what() << std::endl;
            // 可以在这里添加更多的异常处理逻辑
        } catch (...) {
            std::cerr << "Caught an unknown exception in the coroutine" << std::endl;
        }
        // 注意：通常我们不会在这里阻止程序终止，除非我们真的知道如何处理这个异常
        // 在这个例子中，我们仍然调用 std::terminate 来终止程序
        std::terminate();
    }

    // 其他 promise 成员...
};

// 使用自定义 promise 类型的协程句柄类型
using my_coroutine_handle = std::coroutine_handle<my_promise_type>;

// 协程函数
my_coroutine_handle::promise_type foo() {
    co_await std::suspend_always{}; // 挂起点
    throw std::runtime_error("This exception will be caught in unhandled_exception");
}

int main() {
    // 尝试启动协程，但由于异常，它实际上不会完成
    my_coroutine_handle handle = foo();

    // 注意：在实际程序中，我们通常不会直接处理协程句柄
    // 这里的 handle 只是为了演示，实际上我们可能使用更高级别的抽象（如 future/promise）

    // 在这个例子中，由于我们抛出了一个异常，unhandled_exception 将会被调用
    // 并且程序将会终止

    return 0; // 这行代码实际上不会被执行，因为程序在 unhandled_exception 中终止了
}
```

请注意，在实际应用中，通常不会在 `unhandled_exception` 中简单地重新抛出异常并立即调用 `std::terminate`。相反，你可能会记录错误、尝试恢复、或者将异常传递给某个错误处理系统。但是，在很多情况下，如果你不能安全地处理异常，最好的做法还是让程序终止，以避免不确定的行为。