在C++协程中，`set_exception` 是 `std::coroutine_handle` 的一个成员函数，它用于在协程内部设置一个异常。这通常用于当协程函数内部发生异常，但该异常没有被协程体捕获，或者协程体需要显式地将异常传递给协程的调用者时。

`set_exception` 函数接受一个 `std::exception_ptr` 类型的参数，该参数通常是通过 `std::current_exception` 捕获的当前未处理的异常。

以下是一个简单的示例，展示了如何在协程中使用 `set_exception`：

```cpp
#include <iostream>
#include <coroutine>
#include <exception>

// 自定义的 promise 类型
struct my_promise_type {
    std::suspend_always initial_suspend() { return {}; }
    std::suspend_always final_suspend() noexcept { return {}; }
    void unhandled_exception() {
        std::cerr << "Unhandled exception in the coroutine\n";
        std::terminate(); // 默认处理方式，可以自定义
    }
    
    // 其他 promise 成员...
};

// 使用自定义 promise 类型的协程句柄类型
using my_coroutine_handle = std::coroutine_handle<my_promise_type>;

// 协程函数
my_coroutine_handle::promise_type foo() {
    co_await std::suspend_always{}; // 挂起点
    throw std::runtime_error("This exception will be handled in unhandled_exception");
}

// 协程的调用者
void call_coroutine() {
    try {
        my_coroutine_handle handle = foo();
        
        // 这里只是演示，实际上我们不会直接操作协程句柄
        // 通常情况下，协程的调用和恢复是通过更高级别的抽象（如 future/promise）来处理的

        // 假设我们想要显式地设置异常（这通常不是直接操作协程句柄的做法）
        try {
            throw std::runtime_error("Exception set by caller");
        } catch (...) {
            handle.done(); // 标记协程完成
            handle.set_exception(std::current_exception()); // 设置异常
        }

        // 注意：设置异常后，协程的 promise 类型的 unhandled_exception 将会被调用
    } catch (...) {
        // 这里捕获不到协程中设置的异常，因为它是在协程内部处理的
        std::cerr << "Caught an exception in the caller, but not the one set in the coroutine\n";
    }
}

int main() {
    call_coroutine();
    return 0; // 程序将由于 unhandled_exception 中的 std::terminate() 而终止
}
```

**注意**：在实际应用中，你不会直接调用 `set_exception` 来处理协程中的异常。相反，异常是在协程体内部通过 `throw` 语句抛出的，并由协程的 `promise_type` 的 `unhandled_exception` 函数来处理。上面的示例只是为了演示 `set_exception` 的用法，而在实际应用中这种用法是不常见的。

更常见的做法是使用更高级别的抽象（如 `std::future`、`std::jthread`、协程库等）来管理协程的创建、恢复和异常处理。这些抽象通常提供了更易于使用的接口，隐藏了底层协程句柄和 `promise_type` 的复杂性。